#VRML_SIM R2023b utf8

EXTERNPROTO "https://raw.githubusercontent.com/cyberbotics/webots/R2023b/projects/objects/backgrounds/protos/TexturedBackground.proto"
EXTERNPROTO "https://raw.githubusercontent.com/cyberbotics/webots/R2023b/projects/objects/backgrounds/protos/TexturedBackgroundLight.proto"
EXTERNPROTO "https://raw.githubusercontent.com/cyberbotics/webots/R2023b/projects/objects/floors/protos/RectangleArena.proto"
EXTERNPROTO "https://raw.githubusercontent.com/cyberbotics/webots/R2023b/projects/appearances/protos/BrushedAluminium.proto"
EXTERNPROTO "https://raw.githubusercontent.com/cyberbotics/webots/R2023b/projects/objects/balls/protos/Ball.proto"

WorldInfo {
  optimalThreadCount 8
  contactProperties [
    ContactProperties {
      material1 "high_friction_wheel"
      coulombFriction [
        0.4
      ]
      bounce 0
    }
  ]
}
Viewpoint {
  orientation -0.25742815193710694 0.4353757804592863 0.8626579138799534 1.2017393671250498
  position -0.27606764306042547 -0.972290372302383 1.0889663308963717
}
TexturedBackground {
}
TexturedBackgroundLight {
}
RectangleArena {
  floorSize 10 10
  floorTileSize 1 1
  wallHeight 1
}
Ball {
  translation 1.39 0 0.5525
  radius 0.205
}
Robot {
  translation 0.0111246 5.1261e-07 0.325713
  rotation -0.03709331611786788 -0.003989023464898968 -0.9993038444793337 0.00041684231989750785
  children [
    Pose {
      translation 0.08 0 0.11
      children [
        Shape {
          appearance PBRAppearance {
            baseColor 0.666667 0 0
            roughness 1
            metalness 0
          }
          geometry Sphere {
            radius 0.05
          }
        }
        HingeJoint {
          jointParameters HingeJointParameters {
            axis 0 1 0
            minStop -1.5
            maxStop 0.18
          }
          endPoint Solid {
            translation 0.2286 0 0
            rotation 0 1 0 0
            children [
              DEF GRABBER_GEOMETRY Group {
                children [
                  Pose {
                    translation 0.229 0 0
                    children [
                      DEF GRABBER_WIDTH Shape {
                        appearance BrushedAluminium {
                        }
                        geometry Box {
                          size 0.0254 0.4064 0.0254
                        }
                      }
                    ]
                  }
                  Pose {
                    translation 0 -0.215 0
                    children [
                      DEF GRABBER_LENGTH Shape {
                        appearance BrushedAluminium {
                        }
                        geometry Box {
                          size 0.4826 0.0254 0.0254
                        }
                      }
                    ]
                  }
                  Pose {
                    translation 0 0.215 0
                    children [
                      DEF GRABBER_LENGTH Shape {
                        appearance BrushedAluminium {
                        }
                        geometry Box {
                          size 0.4826 0.0254 0.0254
                        }
                      }
                    ]
                  }
                ]
              }
            ]
            boundingObject USE GRABBER_GEOMETRY
            physics Physics {
              mass 20
            }
          }
        }
      ]
    }
    HingeJoint {
      jointParameters HingeJointParameters {
        position 0.4156366003705947
        axis 0 1 0
        anchor 0.29 0.25 0
      }
      device [
        DEF Motor RotationalMotor {
          name "front_left_motor"
          maxVelocity 30
          maxTorque 30
        }
      ]
      endPoint DEF WHEEL1 Solid {
        translation 0.29 0.25 0
        rotation 1 3.925231146709436e-17 0 1.5707963267948968
        children [
          DEF WHEEL Shape {
            appearance PBRAppearance {
              baseColorMap ImageTexture {
                url [
                  "https://raw.githubusercontent.com/cyberbotics/webots/R2023b/projects/appearances/protos/textures/tire_rubber/car_tire_rubber_base_color.jpg"
                ]
              }
              roughnessMap ImageTexture {
                url [
                  "https://raw.githubusercontent.com/cyberbotics/webots/R2023b/projects/appearances/protos/textures/tire_rubber/car_tire_rubber_roughness.jpg"
                ]
              }
              metalness 0
              normalMap ImageTexture {
                url [
                  "https://raw.githubusercontent.com/cyberbotics/webots/R2023b/projects/appearances/protos/textures/tire_rubber/car_tire_rubber_normal.jpg"
                ]
              }
              normalMapFactor 8
              occlusionMap ImageTexture {
                url [
                  "https://raw.githubusercontent.com/cyberbotics/webots/R2023b/projects/appearances/protos/textures/tire_rubber/car_tire_rubber_occlusion.jpg"
                ]
              }
              occlusionMapStrength 8
            }
            geometry Cylinder {
              height 0.05
              radius 0.0762
              subdivision 32
            }
          }
        ]
        name "front_left_motor"
        contactMaterial ""
        boundingObject USE WHEEL
        physics DEF WHEEL_PH Physics {
          density -1
          mass 0.8
        }
      }
    }
    HingeJoint {
      jointParameters HingeJointParameters {
        position 0.41563665647878545
        axis 0 1 0
        anchor -0.29 0.25 0
      }
      device [
        RotationalMotor {
          name "rear_left_motor"
          maxVelocity 30
          maxTorque 30
        }
      ]
      endPoint Solid {
        translation -0.29 0.25 0
        rotation 1 0 0 1.5707963267948968
        children [
          USE WHEEL
        ]
        name "rear_left_motor"
        contactMaterial ""
        boundingObject USE WHEEL
        physics USE WHEEL_PH
      }
    }
    HingeJoint {
      jointParameters HingeJointParameters {
        position 0.41563665647878545
        axis 0 1 0
        anchor 0 0.25 -0.003175
      }
      device [
        RotationalMotor {
          name "middle_left_motor"
          maxVelocity 30
          maxTorque 30
        }
      ]
      endPoint Solid {
        translation 0 0.25 -0.003175
        rotation 1 0 0 1.5707963267948968
        children [
          USE WHEEL
        ]
        name "middle_left_motor"
        contactMaterial ""
        boundingObject USE WHEEL
        physics USE WHEEL_PH
      }
    }
    HingeJoint {
      jointParameters HingeJointParameters {
        position 0.1385732245580487
        axis 0 1 0
        anchor -0.29 -0.25 0
      }
      device [
        RotationalMotor {
          name "rear_right_motor"
          maxVelocity 30
          maxTorque 30
        }
      ]
      endPoint Solid {
        translation -0.29 -0.25 0
        rotation 1 3.925231146709438e-17 0 1.5707963267948966
        children [
          USE WHEEL
        ]
        name "rear_right_motor"
        contactMaterial ""
        boundingObject USE WHEEL
        physics USE WHEEL_PH
      }
    }
    HingeJoint {
      jointParameters HingeJointParameters {
        position 0.1385732245580487
        axis 0 1 0
        anchor 0 -0.25 -0.003175
      }
      device [
        RotationalMotor {
          name "middle_right_motor"
          maxVelocity 30
          maxTorque 30
        }
      ]
      endPoint Solid {
        translation 0 -0.25 -0.003175
        rotation 1 -1.962615573354719e-17 0 1.5707963267948966
        children [
          USE WHEEL
        ]
        name "middle_right_motor"
        contactMaterial ""
        boundingObject USE WHEEL
        physics USE WHEEL_PH
      }
    }
    HingeJoint {
      jointParameters HingeJointParameters {
        position 0.13857319605454727
        axis 0 1 0
        anchor 0.29 -0.25 0
      }
      device [
        RotationalMotor {
          name "front_right_motor"
          maxVelocity 30
          maxTorque 30
        }
      ]
      endPoint Solid {
        translation 0.29 -0.25 0
        rotation 1 1.962615573354719e-17 9.813077866773595e-18 1.5707963267948966
        children [
          USE WHEEL
        ]
        name "front_right_motor"
        contactMaterial ""
        boundingObject USE WHEEL
        physics USE WHEEL_PH
      }
    }
    Solid {
      children [
        DEF CHASSIS_GEOMETRY Group {
          children [
            Pose {
              translation 0 0.32655 0
              children [
                Shape {
                  appearance BrushedAluminium {
                  }
                  geometry DEF ROBOT Box {
                    size 0.813 0.02 0.0762
                  }
                }
              ]
            }
            Pose {
              translation 0 -0.32655 0
              children [
                Shape {
                  appearance BrushedAluminium {
                  }
                  geometry DEF ROBOT Box {
                    size 0.813 0.02 0.0762
                  }
                }
              ]
            }
            Pose {
              translation 0.3965 0 0
              children [
                Shape {
                  appearance BrushedAluminium {
                  }
                  geometry DEF ROBOT Box {
                    size 0.02 0.633 0.0762
                  }
                }
              ]
            }
            Pose {
              translation -0.3965 0 0
              children [
                Shape {
                  appearance BrushedAluminium {
                  }
                  geometry DEF ROBOT Box {
                    size 0.02 0.633 0.0762
                  }
                }
              ]
            }
          ]
        }
      ]
      name "chassis"
      boundingObject USE CHASSIS_GEOMETRY
      physics Physics {
        density -1
        mass 10
      }
    }
  ]
  boundingObject USE ROBOT
  physics Physics {
    density -1
    mass 5
  }
  controller "joystickControl"
}
