#VRML_SIM R2025a utf8

EXTERNPROTO "https://raw.githubusercontent.com/cyberbotics/webots/R2023b/projects/objects/backgrounds/protos/TexturedBackground.proto"
EXTERNPROTO "https://raw.githubusercontent.com/cyberbotics/webots/R2023b/projects/objects/backgrounds/protos/TexturedBackgroundLight.proto"
EXTERNPROTO "https://raw.githubusercontent.com/cyberbotics/webots/R2023b/projects/objects/floors/protos/RectangleArena.proto"
EXTERNPROTO "https://raw.githubusercontent.com/cyberbotics/webots/R2023b/projects/appearances/protos/BrushedAluminium.proto"
EXTERNPROTO "https://raw.githubusercontent.com/cyberbotics/webots/R2023b/projects/objects/balls/protos/Ball.proto"
EXTERNPROTO "../protos/linearActuator.proto"
EXTERNPROTO "../protos/wheel.proto"

WorldInfo {
  optimalThreadCount 8
  contactProperties [
    ContactProperties {
      material1 "high_friction_wheel"
      coulombFriction [
        0.4
      ]
      bounce 0
    }
  ]
}
Viewpoint {
  orientation 0.2912928471205609 -0.5080772940618047 -0.810559029605637 5.051941345877433
  position -0.4756213488598634 -0.8095732557838006 1.0698616928330067
  follow "robot"
}
TexturedBackground {
}
TexturedBackgroundLight {
}
RectangleArena {
  floorSize 10 10
  floorTileSize 1 1
  wallHeight 1
}
Ball {
  translation 0.38 0 1.5925
  radius 0.205
}
Robot {
  translation 0.0111246 5.1261e-07 0.325713
  rotation -0.03709331611786788 -0.003989023464898968 -0.9993038444793337 0.00041684231989750785
  children [
    wheel {
      translation 0.29 0.25 0
      motorName "front_left_motor"
    }
    wheel {
      translation 0 0.25 -0.003175
      motorName "middle_left_motor"
    }
    wheel {
      translation 0 -0.25 -0.003175
      motorName "middle_right_motor"
    }
    wheel {
      translation -0.29 0.25 0
      motorName "rear_left_motor"
    }
    wheel {
      translation 0.29 -0.25 0
      motorName "front_right_motor"
    }
    wheel {
      translation -0.29 -0.25 0
      motorName "rear_right_motor"
    }
    linearActuator {
      translation 0.13 0.22 0.13
      rotation 0 1 0 1.5707963267948968
      maxVelocity 0.014
      endJointUpperActuator "grabber_solid"
      startingStroke 0.08
    }
    Pose {
      translation 0.37 0 0.08
      rotation 0 -1 0 1.5707963267948968
      children [
        Shape {
          appearance PBRAppearance {
            baseColor 0.666667 0 0
            roughness 1
            metalness 0
          }
          geometry Sphere {
            radius 0.05
          }
        }
        HingeJoint {
          jointParameters HingeJointParameters {
            axis 0 1 0
            minStop -0.3
            maxStop 1
            dampingConstant 0.5
          }
          device [
            RotationalMotor {
              name "grabber_attitude"
              maxTorque 100
            }
          ]
          endPoint Solid {
            rotation 0 1 0 0
            children [
              DEF GRABBER_GEOMETRY Group {
                children [
                  Pose {
                    translation 0.558 -0.23 0.11
                    children [
                      Shape {
                        appearance BrushedAluminium {
                        }
                        geometry Box {
                          size 0.1524 0.003175 0.46
                        }
                      }
                    ]
                  }
                  Pose {
                    translation 0.558 -3.69866e-17 0.34
                    rotation 1 0 0 1.5707963267948968
                    children [
                      Shape {
                        appearance BrushedAluminium {
                        }
                        geometry Box {
                          size 0.1524 0.003175 0.46
                        }
                      }
                    ]
                  }
                  Pose {
                    translation 0.558 0.23 0.11
                    children [
                      Shape {
                        appearance BrushedAluminium {
                        }
                        geometry Box {
                          size 0.1524 0.003175 0.46
                        }
                      }
                    ]
                  }
                  Pose {
                    translation 0.508 0 0.11
                    children [
                      Shape {
                        appearance BrushedAluminium {
                        }
                        geometry Box {
                          size 0.0508 0.4572 0.46
                        }
                      }
                    ]
                  }
                  Pose {
                    translation 0.47 0 0
                    children [
                      DEF GRABBER_WIDTH Shape {
                        appearance BrushedAluminium {
                        }
                        geometry Box {
                          size 0.0254 0.4064 0.0254
                        }
                      }
                    ]
                  }
                  Pose {
                    translation 0.229 -0.215 0
                    children [
                      DEF GRABBER_LENGTH Shape {
                        appearance BrushedAluminium {
                        }
                        geometry Box {
                          size 0.508 0.0254 0.0254
                        }
                      }
                    ]
                  }
                  Pose {
                    translation 0.229 0.215 0
                    children [
                      USE GRABBER_LENGTH
                    ]
                  }
                ]
              }
              Pose {
                translation 0.4 0 0
                children [
                  HingeJoint {
                    jointParameters HingeJointParameters {
                      axis 0 1 0
                      dampingConstant 0.5
                    }
                    device [
                      RotationalMotor {
                        name "grabber_roller_motor"
                      }
                    ]
                    endPoint Solid {
                      rotation 1 0 0 1.5707963267948968
                      children [
                        DEF GRABBER_ROLLER_GEOMETRY Shape {
                          appearance PBRAppearance {
                            baseColor 0 0.666667 0
                            roughness 0.8
                            metalness 0.1
                          }
                          geometry Cylinder {
                            height 0.28
                            radius 0.03
                          }
                        }
                      ]
                      boundingObject USE GRABBER_ROLLER_GEOMETRY
                      physics Physics {
                        density -1
                        mass 1
                      }
                    }
                  }
                ]
              }
            ]
            name "grabber_solid"
            boundingObject USE GRABBER_GEOMETRY
            physics Physics {
              density -1
              mass 5
            }
          }
        }
      ]
    }
    Solid {
      children [
        DEF CHASSIS_GEOMETRY Group {
          children [
            Pose {
              translation 0 0.32655 0
              children [
                Shape {
                  appearance BrushedAluminium {
                  }
                  geometry DEF ROBOT Box {
                    size 0.813 0.02 0.0762
                  }
                }
              ]
            }
            Pose {
              translation 0 -0.32655 0
              children [
                Shape {
                  appearance BrushedAluminium {
                  }
                  geometry DEF ROBOT Box {
                    size 0.813 0.02 0.0762
                  }
                }
              ]
            }
            Pose {
              translation 0.3965 0 0
              children [
                Shape {
                  appearance BrushedAluminium {
                  }
                  geometry DEF ROBOT Box {
                    size 0.02 0.633 0.0762
                  }
                }
              ]
            }
            Pose {
              translation -0.3965 0 0
              children [
                Shape {
                  appearance BrushedAluminium {
                  }
                  geometry DEF ROBOT Box {
                    size 0.02 0.633 0.0762
                  }
                }
              ]
            }
          ]
        }
      ]
      name "chassis"
      boundingObject USE CHASSIS_GEOMETRY
      physics Physics {
        density -1
        mass 30
      }
    }
  ]
  boundingObject USE ROBOT
  physics Physics {
    density -1
    mass 5
  }
  controller "joystickControl"
}
